<?xml version="1.0"?>
<robot xmlns:xacro="http://www.ros.org/wiki/xacro" name="manipulator">
    <xacro:macro name="Manipulator" params="parent">

        <!-- ======================= Links ======================= -->

        <link name="BASE">
            <visual>
                <origin xyz="0 0 0.0" rpy="0 -0 0.0127"/>
                <geometry>
                    <mesh filename="package://rover_denso_description/meshes/vs060/base_link.dae" />
                </geometry>
            </visual>
            <collision>
                <origin xyz="0 0 0" rpy="0 -0 0.0127"/>
                <geometry>
                    <mesh filename="package://rover_denso_description/meshes/vs060/base_link.dae" />
                </geometry>
            </collision>
            <inertial>
                <mass value="10" />
                <origin xyz="0 0 0" rpy="0 -0 0"/>
                <inertia ixx="20" ixy="0" ixz="0" iyy="20" iyz="0" izz="20"/>
            </inertial>
        </link>

        <link name="J1">
            <visual>
                <origin xyz="0 0 0" rpy="0 0 0.0127"/>
                <geometry>
                    <mesh filename="package://rover_denso_description/meshes/vs060/J1.dae" />
                </geometry>
            </visual>
            <collision>
                <origin xyz="0 0 0" rpy="0 0 0.0127"/>
                <geometry>
                    <mesh filename="package://rover_denso_description/meshes/vs060/J1.dae" />
                </geometry>
            </collision>
            <inertial>
                <mass value="4.327" />
                <inertia ixx="0.025492" ixy="0" ixz="0" iyy="0.032502" iyz="0.0" izz="0.01779"/>
            </inertial>
        </link>

        <link name="J2">
            <visual>
                <origin xyz="0 0 0" rpy="0 0 0.0127"/>
                <geometry>
                    <mesh filename="package://rover_denso_description/meshes/vs060/J2.dae" />
                </geometry>
            </visual>
            <collision>
                <origin xyz="0 0 0" rpy="0 0 0.0127"/>
                <geometry>
                    <mesh filename="package://rover_denso_description/meshes/vs060/J2.dae" />
                </geometry>
            </collision>
            <inertial>
                <mass value="9.475" />
                <inertia ixx="0.108024" ixy="0" ixz="0" iyy="0.025579" iyz="0.0" izz="0.112871"/>
            </inertial>
        </link>

        <link name="J3">
            <visual>
                <origin xyz="0 0 0" rpy="0 0 0.0127"/>
                <geometry>
                    <mesh filename="package://rover_denso_description/meshes/vs060/J3.dae" />
                </geometry>
            </visual>
            <collision>
                <origin xyz="0 0 0" rpy="0 0 0.0127"/>
                <geometry>
                    <mesh filename="package://rover_denso_description/meshes/vs060/J3.dae" />
                </geometry>
            </collision>
            <inertial>
                <mass value="4.097" />
                <inertia ixx="0.015999" ixy="0" ixz="0" iyy="0.00638" iyz="0.0" izz="0.016882"/>
            </inertial>
        </link>

        <link name="J4">
            <visual>
                <origin xyz="0 0 0" rpy="0 0 0.0127"/>
                <geometry>
                    <mesh filename="package://rover_denso_description/meshes/vs060/J4.dae" />
                </geometry>
            </visual>
            <collision>
                <origin xyz="0 0 0" rpy="0 0 0.0127"/>
                <geometry>
                    <mesh filename="package://rover_denso_description/meshes/vs060/J4.dae" />
                </geometry>
            </collision>
            <inertial>
                <mass value="1.779" />
                <inertia ixx="0.005106" ixy="0" ixz="0" iyy="0.005266" iyz="0.0" izz="0.002621"/>
            </inertial>
        </link>

        <link name="J5">
            <visual>
                <origin xyz="0 0 0" rpy="0 0 0.0127"/>
                <geometry>
                    <mesh filename="package://rover_denso_description/meshes/vs060/J5.dae" />
                </geometry>
            </visual>
            <collision>
                <origin xyz="0 0 0" rpy="0 0 0.0127"/>
                <geometry>
                    <mesh filename="package://rover_denso_description/meshes/vs060/J5.dae" />
                </geometry>
            </collision>
            <inertial>
                <mass value="1.211" />
                <inertia ixx="0.001093" ixy="0" ixz="0" iyy="0.001629" iyz="0.0" izz="0.001615"/>
            </inertial>
        </link>

        <link name="J6">
            <visual>
                <origin xyz="0 0 0" rpy="0 0 0.0127"/>
                <geometry>
                    <mesh filename="package://rover_denso_description/meshes/vs060/J6.dae" />
                </geometry>
            </visual>
            <collision>
                <origin xyz="0 0.0 0.07" rpy="0 0 0.0127"/>
                <geometry>
                    <mesh filename="package://rover_denso_description/meshes/vs060/J6.dae" />
                </geometry>
            </collision>
            <inertial>
                <mass value="2.154" />
                <origin xyz="-0.000401015 0.0770342 0.0962886" rpy="0 0 0"/>
                <inertia ixx="0.0216473" ixy="-0.000147026" ixz="-0.00011778" iyy="0.0346876" iyz="0.00159321" izz="0.022927"/>
            </inertial>
        </link>

        <link name="Endeffector">
            <visual>
                <origin xyz="0 0 0" rpy="0 0 0"/>
                <geometry>
                    <mesh filename="package://rover_denso_description/meshes/endeffector.dae" />
                </geometry>
            </visual>
            <collision>
                <origin xyz="0 0 0" rpy="0 0 0"/>
                <geometry>
                    <mesh filename="package://rover_denso_description/meshes/endeffector.dae" />
                </geometry>
            </collision>
            <inertial>
                <mass value="2.154" />
                <inertia ixx="0.0216473" ixy="-0.000147026" ixz="-0.00011778" iyy="0.0346876" iyz="0.00159321" izz="0.022927"/>
            </inertial>
        </link>

        <link name="Tip"/>

        <!-- ======================= Joints ====================== -->

	    <joint name="base" type="revolute">
            <parent link="${parent}"/>
            <child  link="BASE"/>
            <origin xyz="0 0.0 0.1187" rpy="0 0 0"/>
            <axis xyz="0 0 1" />
            <limit lower="-0.01" upper="0.01" effort="0.0" velocity="0.0"/>
        </joint>

        <joint name="joint_1" type= "revolute">
            <parent link="BASE"/>
            <child  link="J1"/>
            <origin xyz="0 0 0.181500" rpy="0 0 0 "/>
            <axis   xyz="0 0 1"/>
            <limit effort="1000" lower="-2.96706" upper="2.96706" velocity="3.926991"/>
        </joint>

        <joint name="joint_2" type="revolute">
            <parent link="J1"/>
            <child  link="J2"/>
            <origin xyz="0 0 0.163500" rpy="0 0 0"/>
            <axis   xyz="0 1 0"/>
            <limit effort="1000" lower="-2.094395" upper="2.094395" velocity="3.141593"/>
        </joint>

        <joint name="joint_3" type="revolute">
            <parent link="J2"/>
            <child  link="J3"/>
            <origin xyz="0 0 0.305000" rpy="0 0 0 "/>
            <axis   xyz="0 1 0"/>
            <limit effort="1000" lower="-2.094395" upper="2.635447" velocity="3.563962"/>
        </joint>

        <joint name="joint_4" type="revolute">
            <parent link="J3"/>
            <child  link="J4"/>
            <origin xyz="-0.010000 0 0.164500" rpy="0 -0 0 "/>
            <axis   xyz="0 0 1"/>
            <limit effort="1000" lower="-4.712389" upper="4.712389" velocity="3.926991"/>
        </joint>

        <joint name="joint_5" type="revolute">
            <parent link="J4"/>
            <child  link="J5"/>
            <origin xyz="0 0 0.135500" rpy="0 -0 0 "/>
            <axis   xyz="0 1 0"/>
            <limit effort="1000" lower="-2.094395" upper="2.094395" velocity="3.021688"/>
        </joint>

        <joint name="joint_6" type="revolute">
            <parent link="J5"/>
            <child  link="J6"/>
            <origin xyz="0 0 0.070000" rpy="0 -0 0 "/>
            <axis   xyz="0 0 1"/>
            <limit effort="1000" lower="-6.283185" upper="6.283185" velocity="6.283185"/>
        </joint>

        <joint name="endeffector" type="fixed">
            <parent link="J6"/>
            <child  link="Endeffector"/>
            <origin xyz="0 0 0" rpy="0 0 0"/>
        </joint>

        <joint name="tip" type="fixed">
            <origin xyz="0.075508 0 0.419036" rpy="0 0.785398 0"/>
            <parent link="Endeffector"/>
            <child link="Tip"/>
        </joint>

        <!-- ==================== Transmission =================== -->

        <transmission name="trans_base">
            <type>transmission_interface/SimpleTransmission</type>
            <joint name="base">
                <hardwareInterface>hardware_interface/PositionJointInterface</hardwareInterface>
            </joint>
            <actuator name="motor_base">
                <mechanicalReduction>1</mechanicalReduction>
            </actuator>
        </transmission>

        <!-- Manipulator Transmission Macro -->
        <xacro:macro name="manipulator_transmission" params="joint_index">
            <transmission name="trans_${joint_index}">
                <type>transmission_interface/SimpleTransmission</type>
                <joint name="joint_${joint_index}">
                    <hardwareInterface>hardware_interface/PositionJointInterface</hardwareInterface>
                </joint>
                <actuator name="motor_${joint_index}">
                    <mechanicalReduction>1</mechanicalReduction>
                </actuator>
            </transmission>
        </xacro:macro>

        <xacro:manipulator_transmission joint_index="1"/>
        <xacro:manipulator_transmission joint_index="2"/>
        <xacro:manipulator_transmission joint_index="3"/>
        <xacro:manipulator_transmission joint_index="4"/>
        <xacro:manipulator_transmission joint_index="5"/>
        <xacro:manipulator_transmission joint_index="6"/>

        <!-- ======================= Gazebo ====================== -->

        <!-- Manupulator Links Properties Macro -->
        <xacro:macro name="manipulator_link_properties" params="link">
            <gazebo reference="${link}">
                <kp>1000000000000</kp>
                <kd>0.00025</kd>
                <mu1>10.7</mu1>
                <mu2>10.7</mu2>
            </gazebo>
        </xacro:macro>

        <xacro:manipulator_link_properties link="BASE"/>
        <xacro:manipulator_link_properties link="J1"/>
        <xacro:manipulator_link_properties link="J2"/>
        <xacro:manipulator_link_properties link="J3"/>
        <xacro:manipulator_link_properties link="J4"/>
        <xacro:manipulator_link_properties link="J5"/>
        <xacro:manipulator_link_properties link="J6"/>
        <xacro:manipulator_link_properties link="Endeffector"/>

    </xacro:macro>
</robot>

